Workbook

Sheet Index
A1: SEIN PIC | C1: GOAT PIC | E1: FOC TYPE | G1: STATUS | I1: FOC STATUS | K1: TYPE | L1: USEFULL LINK
A2: AKBARI | C2: ABIGAIL | E2: ACCESORIES | G2: AVAILABLE IN AGENCY | I2: RETURN | K2: INT | L2: DASHBOARD | M2: DASHBOARD FOC 2026
A3: ANNELA | C3: ADISTI | E3: APS | G3: EXTENDED | I3: UNRETURN | K3: EXT | L3: OVERDUE SAMPLE | M3: OVERDUE SAMPLE CM
A4: MANDIE | C4: ALIYA | E4: BUDS | G4: GIFT TO KOL | K4: INT | L4: OLIV RAMADAN CAMPAIGN | M4: [INT] Ramadan 2026
A5: RHEINHARD | C5: AUFA | E5: HANDPHONE | G5: LOST | K5: INT | L5: OLD DATA FOC (MBAK LUNA) | M5: https://insidemedia-my.sharepoint.com/:x:/r/personal/dinesh_sharma_wppmedia_com/_layouts/15/Doc.aspx?sourcedoc=%7BF5525DC8-17E5-4A11-A87C-1169ED6ADA3C%7D&file=SAMSUNG%20FOC%20TRACKER.xlsx&action=default&mobileredirect=true
A6: YAYA | C6: CHRISYE | E6: RUGGED | G6: RETURNED TO TCC | K6: INT | L6: SALMA TAB CAMPAIGN | M6: [INT] - Galaxy Tab Series
C7: ISNAINI | E7: TAB
C8: KHALIDA | E8: WEARABLES
C9: LIA
C10: MARTIN
C11: OLIV
C12: REZA
C13: RIZAL
C14: SALMA
C15: SULU
C16: TASHYA
C17: VENNI

Sheet OLD DATA
B1: DATE | C1: CAMP MGMT PIC | D1: FOC CATEGORY | E1: FOC PRODUCT NAME | F1: FOC CAPACITY | G1: FOC COLOUR | H1: FOC IMEI/SN | I1: FOC LOCATION (REMARK) | J1: KOL NAME | K1: FOC STATUS | L1: RETURNED TO GOAT DATE | M1: RETURN METHOD | N1: RECIPIENT NAME (GOAT) | O1: LINK TO SUPPORTING DOC | P1: RETURNED TO CLIENT DATE | Q1: RECEIPIENT (CLIENT) | R1: RETURN METHOD | S1: UPDATED By ( PIC ) | T1: Column2
A2: exp | B2: 45574 | C2: LIA | D2: PHONE | E2: S24 | F2: 512 GB | G2: BLUE | H2: 356789101234567 | I2: LOCKER | K2: RETURNABLE | L2: 45635 | M2: DROP OFF | N2: LUNA | O2: https://insidemedia-my.sharepoint.com/:f:/r/personal/dinesh_sharma_groupm_com/Documents/GROUPM/SAMSUNG/S24%20EXTENDED%20_%20FOC%20DOCUMENT?csf=1&web=1&e=fTUNkO | P2: 46368 | Q2: INDAH | R2: #VALUE!
B3: 45643 | C3: LIA | D3: PHONE | E3: S24 | F3: 256 GB | G3: GRAPHITE | H3: 350009210054786 | I3: WITH KOL | K3: RETURN | O3: EXISTING FOC - 2024 | R3: #VALUE!
B4: 45643 | C4: LIA | D4: PHONE | E4: S24 | F4: 256 GB | G4: GRAPHITE | H4: 350009210062151 | I4: SENT TO CLIENT | K4: RETURN | O4: EXISTING FOC - 2024 | R4: #VALUE!
B5: 45644 | C5: SALMA | D5: PHONE | E5: Galaxy S24 FE | F5: 256 GB | G5: GRAPHITE | H5: 350009210074339 | I5: WITH KOL | J5: Macsson | K5: RETURN | O5: EXISTING FOC - 2024 | R5: #VALUE!
B6: 45643 | C6: LIA | D6: PHONE | E6: S24 | F6: 256 GB | G6: GRAPHITE | H6: 350009210064033 | I6: SENT TO CLIENT | K6: RETURN | O6: EXISTING FOC - 2024 | R6: #VALUE!
B7: 45644 | C7: AUFA | D7: PHONE | E7: Galaxy S24 FE | F7: 256 GB | G7: GRAPHITE | H7: 350009210066285 | I7: SENT TO CLIENT | J7: JKT GO (Ian) | K7: RETURN | L7: 45663 | M7: DELIVERY | O7: EXISTING FOC - 2024 | R7: DEVERY | S7: done
B8: 45643 | C8: LIA | D8: PHONE | E8: S24 | F8: 256 GB | G8: GREY | H8: 350009210024854 | I8: LOCKER | K8: RETURN | O8: EXISTING FOC - 2024 | R8: #VALUE!
B9: 45643 | C9: SALMA | D9: Handphone | E9: Galaxy Z Fold6 | G9: Pink | H9: 359914140006536 | I9: Locker (Dituker untuk Caca Tengker) | K9: Unreturn | R9: #VALUE!
B10: 45643 | C10: SALMA | D10: Handphone | E10: Galaxy Z Fold6 | G10: Pink | H10: 359890570001884 | I10: Locker | K10: Unreturn | R10: #VALUE! | S10: ?
B11: 45643 | C11: SALMA | D11: Handphone | E11: Galaxy Z Fold6 | F11: 256 GB | G11: Pink | H11: 359890570004508 | I11: SENT TO CLIENT | J11: *Udah ditukar dari Caca Tengker | K11: Return | P11: 45680 | Q11: INTAN | R11: #VALUE!
B12: 45643 | C12: SALMA | D12: Handphone | E12: Galaxy Z Fold6 | G12: Pink | H12: 359890570002007 | I12: SENT TO CLIENT | K12: Return | P12: 45680 | Q12: INTAN | R12: #VALUE!
B13: 45643 | C13: SALMA | D13: Handphone | E13: Galaxy Z Fold6 | G13: Navy | H13: 359890570026550 | I13: SENT TO CLIENT | K13: Return | P13: 45680 | Q13: INTAN | R13: #VALUE!
B14: 45643 | C14: SALMA | D14: Handphone | E14: Galaxy Z Flip6 | G14: Blue | H14: 358899540128439 | I14: SENT TO CLIENT | K14: Return | P14: 45996 | Q14: AKBARI | R14: #VALUE!
B15: 45644 | C15: SALMA | D15: Handphone | E15: Galaxy Z Flip6 | F15: 256 GB | G15: Yellow | H15: 355541740043868 | I15: SENT TO CLIENT | K15: Return | R15: #VALUE!
B16: 45643 | C16: SALMA | D16: Handphone | E16: Galaxy Z Flip6 | F16: 256 GB | G16: Silver Shadow | H16: 355541740040054 | I16: SENT TO CLIENT | K16: Return | L16: 45665 | M16: DELIVERY | N16: ABIGAIL | R16: DEVERY | S16: Done
B17: 45643 | C17: SALMA | D17: Handphone | E17: Galaxy Z Flip6 | F17: 256 GB | G17: Silver Shadow | H17: 355735480090556 | I17: WITH KOL | J17: DIDIET MAULANA | K17: Unreturn | R17: #VALUE! | S17: ?
B18: 45643 | C18: SALMA | D18: Handphone | E18: Galaxy Z Flip6 | F18: 256 GB | G18: Mint | H18: 355725480013889 | I18: Locker | K18: Unreturn | R18: #VALUE! | S18: ?
B19: 45643 | C19: SALMA | D19: Handphone | E19: Galaxy Z Flip6 | G19: Yellow | H19: 355541740043934 | I19: SENT TO CLIENT | K19: Return | R19: #VALUE!
B20: 45643 | D20: Handphone | E20: S 24 Ultra | F20: 256 GB | G20: Titanium Black | H20: 352722665255306 | I20: Locker | K20: Unreturn | R20: DEVEUS | S20: Done
B21: 45643 | D21: Handphone | E21: S 24 Ultra | G21: Titanium Yellow | H21: 352722665041466 | I21: Box only, no device | K21: Return | R21: #VALUE!
B22: 45643 | D22: Handphone | E22: S 24 Ultra | G22: Titanium Gray | H22: 353892182010341 | I22: Box only, no device | K22: Return | R22: #VALUE!
B23: 45643 | C23: MARTIN | D23: Handphone | E23: S 24 Ultra | G23: Titanium Gray | H23: 352722665018076 | I23: Box only, no device | K23: Return | R23: #VALUE!
B24: 45643 | D24: Handphone | E24: S24 Base | F24: 512 GB | G24: Marble Gray | H24: 354730495019162 | I24: Locker | K24: Return | R24: DEVER4 | S24: Done
B25: 45643 | C25: DHYFA | D25: Handphone | E25: S24 Base | G25: Cobalt Violet | H25: 354267935002797 | I25: SENT TO CLIENT | K25: Return | R25: #VALUE! | S25: ?
B26: 45643 | C26: DHYFA | D26: Handphone | E26: S24 Base | G26: Onyx Black | H26: 354267935021300 | I26: SENT TO CLIENT | K26: Return | L26: 45665 | M26: DELIVERY | N26: ABIGAIL | P26: 45667 | Q26: AULIA | R26: DELIVERY | S26: ?
B27: 45643 | C27: DHYFA | D27: Handphone | E27: S23 Ultra | G27: Green | H27: 351198920663108 | I27: SENT TO CLIENT | K27: Return | S27: ?
B28: 45643 | C28: DHYFA | D28: Handphone | E28: S23 Ultra | G28: Green | H28: 351198920624563 | I28: SENT TO CLIENT | K28: Return | S28: ?
B29: 45643 | C29: DHYFA | D29: Handphone | E29: S23 Ultra | G29: Green | H29: 351198920624068 | I29: SENT TO CLIENT | K29: Return | S29: ?
B30: 45643 | D30: Handphone | E30: Galaxy S24 FE | G30: Graphite | H30: 350009210002587 | I30: Locker (Ka Martin 11/8/2024) | K30: Unreturn
B31: 45643 | D31: Handphone | E31: Galaxy S24 FE | G31: Graphite | H31: 350009210058175 | I31: Locker (Ka Martin 11/8/2024) | K31: Unreturn
B32: 45643 | D32: Handphone | E32: Galaxy S24 FE | G32: Gray | H32: 350009210023914 | I32: Locker (Ka Martin 11/8/2024) | K32: Unreturn
B33: 45643 | C33: MARTIN | D33: Handphone | E33: Galaxy S24 FE | F33: 256 GB | G33: Graphite | H33: 350009210002413 | I33: SENT TO CLIENT | J33: SALSA OLE | K33: Return | S33: ?
B34: 45643 | C34: MARTIN | D34: Handphone | E34: Galaxy S24 FE | F34: 256 GB | G34: Graphite | H34: 350009210062094 | I34: WITH KOL | J34: MUHAMMAD ALFIAN | K34: Return | S34: ?
B35: 45643 | C35: AUFA | D35: PHONE | E35: Galaxy S24 FE | F35: 256 GB | G35: GRAPHITE | H35: 350009210016744 | I35: SENT TO CLIENT | K35: RETURN | S35: Done
B36: 45643 | D36: Galaxy Watch | E36: Galaxy Watch 6 | G36: Graphite | H36: RFAX10YY4EM | I36: Locker | K36: Return | S36: Done
B37: 45643 | D37: Galaxy Watch | E37: Galaxy Watch 6 | G37: Graphite | H37: RFAW71GBB0A | I37: Locker | K37: Return | S37: Done
B38: 45643 | C38: DHYFA | D38: Galaxy Watch | E38: Galaxy Watch 7 | G38: Silver | H38: RFAX70F1GTV | I38: WITH KOL | K38: Unreturn | S38: ?
B39: 45643 | C39: DHYFA | D39: Galaxy Watch | E39: Galaxy Watch 7 | G39: Green | H39: 2424B75EF785 | I39: WITH KOL | K39: Unreturn | S39: ?
B40: 45643 | D40: Galaxy Watch | E40: Galaxy Watch 7 | G40: Silver | H40: RFAX0F2BEH | I40: Locker | K40: Unreturn | S40: Done
...

Sheet OLD DATA Venni
A1: Salma Maharani Putri Zulkarnaen | B1: DATE | C1: CAMP MGMT PIC | D1: FOC CATEGORY | E1: FOC PRODUCT NAME | F1: FOC CAPACITY | G1: FOC COLOUR | H1: FOC IMEI/SN | I1: FOC LOCATION (REMARK) | J1: KOL NAME | K1: FOC STATUS | L1: RETURNED TO GOAT DATE | M1: RETURN METHOD | N1: RECIPIENT NAME (GOAT) | O1: LINK TO SUPPORTING DOC | P1: RETURNED TO CLIENT DATE | Q1: RECEIPIENT (CLIENT) | R1: RETURN METHOD | S1: Column1 | T1: Column2
A2: Audcharaporn Sada | B2: 45849 | C2: SALMA | D2: HANDPHONE | E2: Galaxy Z Fold7 | F2: 256 GB | G2: Silver Shadow | H2: 354312420005291 | I2: locker | J2: ? | K2: NON-RETURNABLE | R2: #VALUE!
A3: Fenny Christien | B3: 45849 | C3: SALMA | D3: HANDPHONE | E3: Galaxy Z Flip7 | F3: 256 GB | G3: Coralred | H3: 354312420005978 | I3: LOCKER | J3: Naura Ayu | K3: NON-RETURNABLE | R3: #VALUE!
A4: Tris Finalia | B4: 45849 | C4: SALMA | D4: HANDPHONE | E4: Galaxy Z Flip7 | F4: 256 GB | G4: Coralred | H4: 354312420003650 | I4: LOCKER | J4: Di Kantor | K4: NON-RETURNABLE | L4: di xaxa | M4: Mau ditarik | R4: #VALUE!
B5: 45849 | C5: SALMA | D5: HANDPHONE | E5: Galaxy Z Flip7 | F5: 256 GB | G5: Coralred | H5: 354312420003726 | I5: KOL | J5: Ziva Magnolya | K5: NON-RETURNABLE
B6: 45849 | C6: SALMA | D6: HANDPHONE | E6: Galaxy Z Flip7 | F6: 256 GB | G6: Coralred | H6: 354312420006034 | I6: KOL | J6: Ariel Tatum | K6: NON-RETURNABLE
B7: 45849 | C7: SALMA | D7: HANDPHONE | E7: Galaxy Z Flip7 | F7: 256 GB | G7: Coralred | H7: 354312420005168 | I7: KOL | J7: KOL (Creator showdown) | K7: NON-RETURNABLE
B8: 45849 | C8: SALMA | D8: HANDPHONE | E8: Galaxy Z Flip7 | F8: 256 GB | G8: Coralred | H8: 354312420004609 | I8: LOCKER | J8: Vannesa Priscilla | K8: NON-RETURNABLE
B9: 45849 | C9: SALMA | D9: HANDPHONE | E9: Galaxy Z Flip7 | F9: 256 GB | G9: Coralred | H9: 354312420005101 | I9: KOL | J9: Febby Rastanti | K9: NON-RETURNABLE
B10: 45849 | C10: SALMA | D10: HANDPHONE | E10: Galaxy Z Flip7 | F10: 256 GB | G10: Coralred | H10: 354312420003460 | I10: LOCKER | J10: Sissy Priscilla | K10: NON-RETURNABLE
B11: 45849 | C11: SALMA | D11: HANDPHONE | E11: Galaxy Z Flip7 | F11: 512 GB | G11: Coralred | H11: 351691180001910 | I11: di kantor | J11: Di kantor | K11: NON-RETURNABLE
B12: 45849 | C12: SALMA | D12: HANDPHONE | E12: Galaxy Z Flip7 | F12: 256 GB | G12: Blue Shadow | H12: 354312420019045 | I12: KOL | J12: KOL (Creator showdown) | K12: NON-RETURNABLE
B13: 45850 | C13: SALMA | D13: HANDPHONE | E13: Galaxy Z Flip7 | F13: 256 GB | G13: Blue Shadow | H13: 354312420026305 | I13: KOL | J13: Zee Asadel | K13: NON-RETURNABLE
B14: 45851 | C14: SALMA | D14: HANDPHONE | E14: Galaxy Z Flip7 | F14: 256 GB | G14: Blue Shadow | H14: 354312420016298 | I14: KOL | J14: Andovi | K14: NON-RETURNABLE
B15: 45849 | C15: SALMA | D15: HANDPHONE | E15: Galaxy Z Flip7 | F15: 256 GB | G15: Blue Shadow | H15: 354312420016223 | I15: KOL | J15: Widiras | K15: NON-RETURNABLE | M15: Mau ditarik
B16: 45849 | C16: SALMA | D16: HANDPHONE | E16: Galaxy Z Flip7 | F16: 256 GB | G16: Blue Shadow | H16: 354312420022171 | I16: KOL | J16: Vidi Aldiano | K16: NON-RETURNABLE | O16: https://drive.google.com/file/d/1zBbkBjvAte6RUTKECKwHptIXuwOewZzk/view?usp=sharing
B17: 45849 | C17: SALMA | D17: HANDPHONE | E17: Galaxy Z Flip7 | F17: 256 GB | G17: Blue Shadow | H17: 354312420023609 | I17: KOL | J17: Sabian | K17: NON-RETURNABLE | L17: udah di Tarik katanya
B18: 45849 | C18: SALMA | D18: HANDPHONE | E18: Galaxy Z Flip7 | F18: 256 GB | G18: Blue Shadow | H18: 354312420023625 | I18: LOCKER - 3 FEB | J18: Di kantor | K18: NON-RETURNABLE | M18: Mau ditarik
B19: 45849 | C19: SALMA | D19: HANDPHONE | E19: Galaxy Z Flip7 | F19: 256 GB | G19: Blue Shadow | H19: 354312420014004 | I19: LOCKER | J19: Dave Hendrik | K19: NON-RETURNABLE
B20: 45849 | C20: SALMA | D20: HANDPHONE | E20: Galaxy Z Flip7 | F20: 256 GB | G20: Jetblack | H20: 354312420000441 | I20: KOL | J20: Jejouw | K20: NON-RETURNABLE
B21: 45849 | C21: SALMA | D21: HANDPHONE | E21: Galaxy Z Flip7 | F21: 256 GB | G21: Jetblack | H21: 354312420001514 | I21: LOCKER | J21: Di Kantor | K21: NON-RETURNABLE
B22: 45849 | C22: SALMA | D22: HANDPHONE | E22: Galaxy Z Flip7 | F22: 256 GB | G22: Jetblack | H22: 354312420001241 | I22: LOCKER | J22: Di Kantor | K22: NON-RETURNABLE
B23: 45849 | C23: SALMA | D23: HANDPHONE | E23: Galaxy Z Flip7 | F23: 256 GB | G23: Jetblack | H23: 354312420001548 | I23: LOCKER | J23: Dikta | K23: NON-RETURNABLE
B24: 45849 | C24: SALMA | D24: HANDPHONE | E24: Galaxy Z Flip7 | F24: 256 GB | G24: Jetblack | H24: 354312420000268 | I24: LOCKER | J24: Di Kantor | K24: NON-RETURNABLE | L24: Nabila Ishma | M24: Mau ditarik
B25: 45849 | C25: SALMA | D25: HANDPHONE | E25: Galaxy Z Flip7 | F25: 256 GB | G25: Mint | H25: 354312420002603 | I25: KOL | J25: Keshya | K25: NON-RETURNABLE | L25: Keshya | M25: Mau ditarik
B26: 45849 | C26: SALMA | D26: HANDPHONE | E26: Galaxy Z Flip7 | F26: 256 GB | G26: Mint | H26: 354312420002165 | I26: KOL | J26: Alegeor | K26: NON-RETURNABLE | O26: https://drive.google.com/file/d/1dfQE8nvwW31BgTKppCggnTFJKRHDp_mh/view?usp=sharing
B27: 45849 | C27: SALMA | D27: HANDPHONE | E27: Galaxy Z Fold7 | F27: 256 GB | G27: Silver Shadow | H27: Marischka Prudence | I27: LOCKER | K27: NON-RETURNABLE
B28: 45849 | C28: SALMA | D28: HANDPHONE | E28: Galaxy Z Fold7 | F28: 256 GB | G28: Silver Shadow | H28: 355626620006257 | I28: KOL | J28: KOL (Creator showdown) | K28: NON-RETURNABLE
B29: 45849 | C29: SALMA | D29: HANDPHONE | E29: Galaxy Z Fold7 | F29: 256 GB | G29: Silver Shadow | H29: 355626620007495 | I29: KOL | J29: Donne | K29: NON-RETURNABLE | L29: Donne | M29: Dikasih
B30: 45849 | C30: SALMA | D30: HANDPHONE | E30: Galaxy Z Fold7 | F30: 256 GB | G30: Silver Shadow | H30: 355626620007164 | I30: KOL | J30: Adib | K30: NON-RETURNABLE | L30: kotak sama hp beda imei | M30: sudah ditarik
B31: 45849 | C31: SALMA | D31: HANDPHONE | E31: Galaxy Z Fold7 | F31: 256 GB | G31: Silver Shadow | H31: 355626620005291 | I31: LOCKER | J31: mau kasi sadam | K31: NON-RETURNABLE
B32: 45849 | C32: SALMA | D32: HANDPHONE | E32: Galaxy Z Fold7 | F32: 256 GB | G32: Silver Shadow | H32: 355626620007362 | I32: KOL | J32: Galang | K32: NON-RETURNABLE
B33: 45849 | C33: SALMA | D33: HANDPHONE | E33: Galaxy Z Fold7 | F33: 256 GB | G33: Blue Shadow | H33: 355626620017056 | I33: KOL | J33: Nita Vior | K33: NON-RETURNABLE | O33: https://drive.google.com/file/d/1Xg1hwUjowl4h-w1bdd-E2LHovkXMUM0D/view?usp=sharing
B34: 45849 | C34: SALMA | D34: HANDPHONE | E34: Galaxy Z Fold7 | F34: 256 GB | G34: Blue Shadow | H34: 355626620015407 | I34: KOL | J34: Omara | K34: NON-RETURNABLE
B35: 45849 | C35: SALMA | D35: HANDPHONE | E35: Galaxy Z Fold7 | F35: 256 GB | G35: Blue Shadow | H35: 355626620018500 | I35: KOL | J35: Darius | K35: NON-RETURNABLE
B36: 45849 | C36: SALMA | D36: HANDPHONE | E36: Galaxy Z Fold7 | F36: 256 GB | G36: Blue Shadow | H36: 355626620019656 | I36: KOL | J36: Afif Yulistian | K36: NON-RETURNABLE
B37: 45849 | C37: SALMA | D37: HANDPHONE | E37: Galaxy Z Fold7 | F37: 256 GB | G37: Blue Shadow | H37: 355626620016280 | I37: KOL | J37: Hyperlocal | K37: NON-RETURNABLE
B38: 45849 | C38: SALMA | D38: HANDPHONE | E38: Galaxy Z Fold7 | F38: 512 GB | G38: Blue Shadow | H38: 356335510003130 | I38: KOL | J38: Bryan Domani | K38: NON-RETURNABLE
B39: 45849 | C39: SALMA | D39: HANDPHONE | E39: Galaxy Z Fold7 | F39: 512 GB | G39: Blue Shadow | H39: 356335510003817 | I39: LOCKER | J39: Rifat Sungkar | K39: NON-RETURNABLE
B40: 45849 | C40: SALMA | D40: HANDPHONE | E40: Galaxy Z Fold7 | F40: 512 GB | G40: Blue Shadow | H40: 356335510003924 | I40: KOL | J40: Arief Muhammad | K40: NON-RETURNABLE | O40: https://drive.google.com/file/d/1xklgfwtw0_zj4Wooe3FGO6QmoscSK9xN/view?usp=sharing
...

Sheet Mindshare DATA
B1: Serial number wih Check digit | C1: 2nd IMEI no | D1: Material Number | E1: Reference Name1 | F1: Validate | G1: Device name
B2: 351690530003519 | C2: 352380640003513 | D2: SM-S942BZVCXID | E2: REDCOMM INDONESIA | F2: =IFERROR(IF(ISNUMBER(MATCH(B2,'Step 1 Data Bank'!E:E, 0)), "Find", "Not Find"),"") -> Not Find | G2: {=XLOOKUP(B2,'Step 1 Data Bank'!E:E,'Step 1 Data Bank'!F:F)} -> #N/A
B3: 351690530003956 | C3: 352380640003950 | D3: SM-S942BZVCXID | E3: MINDSHARE | F3: =IFERROR(IF(ISNUMBER(MATCH(B3,'Step 1 Data Bank'!E:E, 0)), "Find", "Not Find"),"") -> Not Find | G3: {=XLOOKUP(B3,'Step 1 Data Bank'!E:E,'Step 1 Data Bank'!F:F)} -> #N/A
B4: 351690530004327 | C4: 352380640004321 | D4: SM-S942BZKCXID | E4: MINDSHARE | F4: =IFERROR(IF(ISNUMBER(MATCH(B4,'Step 1 Data Bank'!E:E, 0)), "Find", "Not Find"),"") -> Not Find | G4: {=XLOOKUP(B4,'Step 1 Data Bank'!E:E,'Step 1 Data Bank'!F:F)} -> #N/A
B5: 351690530004418 | C5: 352380640004412 | D5: SM-S942BZKCXID | E5: MINDSHARE | F5: =IFERROR(IF(ISNUMBER(MATCH(B5,'Step 1 Data Bank'!E:E, 0)), "Find", "Not Find"),"") -> Not Find | G5: {=XLOOKUP(B5,'Step 1 Data Bank'!E:E,'Step 1 Data Bank'!F:F)} -> #N/A
B6: 351690530004806 | C6: 352380640004800 | D6: SM-S942BZKCXID | E6: REDCOMM INDONESIA | F6: =IFERROR(IF(ISNUMBER(MATCH(B6,'Step 1 Data Bank'!E:E, 0)), "Find", "Not Find"),"") -> Not Find | G6: {=XLOOKUP(B6,'Step 1 Data Bank'!E:E,'Step 1 Data Bank'!F:F)} -> #N/A
B7: 351690530004988 | C7: 352380640004982 | D7: SM-S942BZKCXID | E7: REDCOMM INDONESIA | F7: =IFERROR(IF(ISNUMBER(MATCH(B7,'Step 1 Data Bank'!E:E, 0)), "Find", "Not Find"),"") -> Not Find | G7: {=XLOOKUP(B7,'Step 1 Data Bank'!E:E,'Step 1 Data Bank'!F:F)} -> #N/A
B8: 351690530005167 | C8: 352380640005161 | D8: SM-S942BZKCXID | E8: REDCOMM INDONESIA | F8: =IFERROR(IF(ISNUMBER(MATCH(B8,'Step 1 Data Bank'!E:E, 0)), "Find", "Not Find"),"") -> Not Find | G8: {=XLOOKUP(B8,'Step 1 Data Bank'!E:E,'Step 1 Data Bank'!F:F)} -> #N/A
B9: 351690530005431 | C9: 352380640005435 | D9: SM-S942BZKCXID | E9: MINDSHARE | F9: =IFERROR(IF(ISNUMBER(MATCH(B9,'Step 1 Data Bank'!E:E, 0)), "Find", "Not Find"),"") -> Not Find | G9: {=XLOOKUP(B9,'Step 1 Data Bank'!E:E,'Step 1 Data Bank'!F:F)} -> #N/A
B10: 351690530005613 | C10: 352380640005617 | D10: SM-S942BZKCXID | E10: REDCOMM INDONESIA | F10: =IFERROR(IF(ISNUMBER(MATCH(B10,'Step 1 Data Bank'!E:E, 0)), "Find", "Not Find"),"") -> Not Find | G10: {=XLOOKUP(B10,'Step 1 Data Bank'!E:E,'Step 1 Data Bank'!F:F)} -> #N/A
B11: 351690530005787 | C11: 352380640005781 | D11: SM-S942BZKCXID | E11: REDCOMM INDONESIA | F11: =IFERROR(IF(ISNUMBER(MATCH(B11,'Step 1 Data Bank'!E:E, 0)), "Find", "Not Find"),"") -> Not Find | G11: {=XLOOKUP(B11,'Step 1 Data Bank'!E:E,'Step 1 Data Bank'!F:F)} -> #N/A
B12: 351690530005902 | C12: 352380640005906 | D12: SM-S942BZKCXID | E12: MINDSHARE | F12: =IFERROR(IF(ISNUMBER(MATCH(B12,'Step 1 Data Bank'!E:E, 0)), "Find", "Not Find"),"") -> Not Find | G12: {=XLOOKUP(B12,'Step 1 Data Bank'!E:E,'Step 1 Data Bank'!F:F)} -> #N/A
B13: 351690530025538 | C13: 352380640025532 | D13: SM-S942BZSCXID | E13: MINDSHARE | F13: =IFERROR(IF(ISNUMBER(MATCH(B13,'Step 1 Data Bank'!E:E, 0)), "Find", "Not Find"),"") -> Find | G13: {=XLOOKUP(B13,'Step 1 Data Bank'!E:E,'Step 1 Data Bank'!F:F)} -> G-S26 256GB SILVER
... B54: 358780495051836 | C54: 358958305051838 | D54: SM-S948BLBBXID | E54: REDCOMM INDONESIA | F54: =IFERROR(IF(ISNUMBER(MATCH(B54,'Step 1 Data Bank'!E:E, 0)), "Find", "Not Find"),"") -> Not Find | G54: {=XLOOKUP(B54,'Step 1 Data Bank'!E:E,'Step 1 Data Bank'!F:F)} -> #N/A

Sheet Step 1 Data Bank
A1: c | B1: DATE OF RECEIPT | C1: SEIN PIC NAME | D1: FOC TYPE | E1: SERIAL NUMBER (IMEI/SN) | F1: UNIT NAME | G1: FOC STATUS | H1: PLANNED RETURN DATE | I1: RECEIVED DATE TIME STAMP (LINK) | J1: GOAT PIC (PLANNER) | K1: CAMPAIGN NAME | L1: STATUS | M1: STATUS LOCATION | N1: ON HOLDER | O1: RETURN TO TCC RECEIPT (LINK) | P1: COMMENTS
B2: 46065 | C2: YAYA | D2: HANDPHONE | E2: 351225503076083 | F2: G-A07 RAMADHAN PACKAGE | G2: RETURN | H2: 46172 | J2: TASHYA | L2: AVAILABLE IN AGENCY | M2: =IF(E2="", "", IF(W2=0, "AVAILABLE", IF(W2 > X2, "LOANED / ON KOL", "AVAILABLE"))) -> LOANED / ON KOL | N2: {=IF(M2="LOANED / ON KOL", INDEX('Step 3 FOC Request'!$G:$G, MATCH(1, ('Step 3 FOC Request'!$A:$A=W2) * ('Step 3 FOC Request'!$F:$F=E2), 0)), "-")} -> Mushdalifah ( Aman) | W2: =MAXIFS('Step 3 FOC Request'!$A:$A, 'Step 3 FOC Request'!$F:$F, $E2) -> 46084.639 | X2: =MAXIFS('Step 4 FOC Return'!$A:$A, 'Step 4 FOC Return'!$E:$E, $E2) -> 0
B3: 46065 | C3: YAYA | D3: HANDPHONE | E3: 351225503087627 | F3: G-A07 RAMADHAN PACKAGE | G3: RETURN | H3: 46172 | J3: TASHYA | L3: AVAILABLE IN AGENCY | M3: =IF(E3="", "", IF(W3=0, "AVAILABLE", IF(W3 > X3, "LOANED / ON KOL", "AVAILABLE"))) -> LOANED / ON KOL | N3: {=IF(M3="LOANED / ON KOL", INDEX('Step 3 FOC Request'!$G:$G, MATCH(1, ('Step 3 FOC Request'!$A:$A=W3) * ('Step 3 FOC Request'!$F:$F=E3), 0)), "-")} -> AMHAD FADHILLA | W3: =MAXIFS('Step 3 FOC Request'!$A:$A, 'Step 3 FOC Request'!$F:$F, $E3) -> 46072.602 | X3: =MAXIFS('Step 4 FOC Return'!$A:$A, 'Step 4 FOC Return'!$E:$E, $E3) -> 0
B4: 46065 | C4: YAYA | D4: HANDPHONE | E4: 351225503088054 | F4: G-A07 RAMADHAN PACKAGE | G4: RETURN | H4: 46172 | J4: TASHYA | L4: AVAILABLE IN AGENCY | M4: =IF(E4="", "", IF(W4=0, "AVAILABLE", IF(W4 > X4, "LOANED / ON KOL", "AVAILABLE"))) -> AVAILABLE | N4: {=IF(M4="LOANED / ON KOL", INDEX('Step 3 FOC Request'!$G:$G, MATCH(1, ('Step 3 FOC Request'!$A:$A=W4) * ('Step 3 FOC Request'!$F:$F=E4), 0)), "-")} -> - | W4: =MAXIFS('Step 3 FOC Request'!$A:$A, 'Step 3 FOC Request'!$F:$F, $E4) -> 0 | X4: =MAXIFS('Step 4 FOC Return'!$A:$A, 'Step 4 FOC Return'!$E:$E, $E4) -> 0
B5: 46065 | C5: YAYA | D5: HANDPHONE | E5: 351225503077255 | F5: G-A07 RAMADHAN PACKAGE | G5: RETURN | H5: 46172 | J5: TASHYA | L5: AVAILABLE IN AGENCY | M5: =IF(E5="", "", IF(W5=0, "AVAILABLE", IF(W5 > X5, "LOANED / ON KOL", "AVAILABLE"))) -> LOANED / ON KOL | N5: {=IF(M5="LOANED / ON KOL", INDEX('Step 3 FOC Request'!$G:$G, MATCH(1, ('Step 3 FOC Request'!$A:$A=W5) * ('Step 3 FOC Request'!$F:$F=E5), 0)), "-")} -> Helin Alvia | W5: =MAXIFS('Step 3 FOC Request'!$A:$A, 'Step 3 FOC Request'!$F:$F, $E5) -> 46079.744 | X5: =MAXIFS('Step 4 FOC Return'!$A:$A, 'Step 4 FOC Return'!$E:$E, $E5) -> 0
B6: 46065 | C6: YAYA | D6: BUDS | E6: RF7L1060V4E | F6: G-BUDS4-PRO GOLD (2026) | G6: RETURN | H6: 46203 | J6: ABIGAIL | K6: Galaxy Buds4 Launch | L6: AVAILABLE IN AGENCY | M6: =IF(E6="", "", IF(W6=0, "AVAILABLE", IF(W6 > X6, "LOANED / ON KOL", "AVAILABLE"))) -> LOANED / ON KOL | N6: {=IF(M6="LOANED / ON KOL", INDEX('Step 3 FOC Request'!$G:$G, MATCH(1, ('Step 3 FOC Request'!$A:$A=W6) * ('Step 3 FOC Request'!$F:$F=E6), 0)), "-")} -> Jeffry Reksa | W6: =MAXIFS('Step 3 FOC Request'!$A:$A, 'Step 3 FOC Request'!$F:$F, $E6) -> 46073.686 | X6: =MAXIFS('Step 4 FOC Return'!$A:$A, 'Step 4 FOC Return'!$E:$E, $E6) -> 0
B7: 46065 | C7: YAYA | D7: BUDS | E7: RF7L1060SQJ | F7: G-BUDS4-PRO GOLD (2026) | G7: RETURN | H7: 46203 | J7: ABIGAIL | K7: Galaxy Buds4 Launch | L7: AVAILABLE IN AGENCY | M7: =IF(E7="", "", IF(W7=0, "AVAILABLE", IF(W7 > X7, "LOANED / ON KOL", "AVAILABLE"))) -> LOANED / ON KOL | N7: {=IF(M7="LOANED / ON KOL", INDEX('Step 3 FOC Request'!$G:$G, MATCH(1, ('Step 3 FOC Request'!$A:$A=W7) * ('Step 3 FOC Request'!$F:$F=E7), 0)), "-")} -> Maysha Juan | W7: =MAXIFS('Step 3 FOC Request'!$A:$A, 'Step 3 FOC Request'!$F:$F, $E7) -> 46090.693 | X7: =MAXIFS('Step 4 FOC Return'!$A:$A, 'Step 4 FOC Return'!$E:$E, $E7) -> 0
B8: 46065 | C8: YAYA | D8: BUDS | E8: RF7L106VRMY | F8: G-BUDS4-PRO WHITE (2026) | G8: RETURN | H8: 46203 | J8: ABIGAIL | K8: Galaxy Buds4 Launch | L8: AVAILABLE IN AGENCY | M8: =IF(E8="", "", IF(W8=0, "AVAILABLE", IF(W8 > X8, "LOANED / ON KOL", "AVAILABLE"))) -> LOANED / ON KOL | N8: {=IF(M8="LOANED / ON KOL", INDEX('Step 3 FOC Request'!$G:$G, MATCH(1, ('Step 3 FOC Request'!$A:$A=W8) * ('Step 3 FOC Request'!$F:$F=E8), 0)), "-")} -> Jevin Julian | W8: =MAXIFS('Step 3 FOC Request'!$A:$A, 'Step 3 FOC Request'!$F:$F, $E8) -> 46085.693 | X8: =MAXIFS('Step 4 FOC Return'!$A:$A, 'Step 4 FOC Return'!$E:$E, $E8) -> 0
B9: 46065 | C9: YAYA | D9: BUDS | E9: RF7L106VRRN | F9: G-BUDS4-PRO WHITE (2026) | G9: RETURN | H9: 46203 | J9: ABIGAIL | K9: Galaxy Buds4 Launch | L9: AVAILABLE IN AGENCY | M9: =IF(E9="", "", IF(W9=0, "AVAILABLE", IF(W9 > X9, "LOANED / ON KOL", "AVAILABLE"))) -> LOANED / ON KOL | N9: {=IF(M9="LOANED / ON KOL", INDEX('Step 3 FOC Request'!$G:$G, MATCH(1, ('Step 3 FOC Request'!$A:$A=W9) * ('Step 3 FOC Request'!$F:$F=E9), 0)), "-")} -> Naura Ayu | W9: =MAXIFS('Step 3 FOC Request'!$A:$A, 'Step 3 FOC Request'!$F:$F, $E9) -> 46079.575 | X9: =MAXIFS('Step 4 FOC Return'!$A:$A, 'Step 4 FOC Return'!$E:$E, $E9) -> 0
B10: 46065 | C10: ANNELA | D10: HANDPHONE | E10: 354312420000854 | F10: G-Z-FLIP7 256GB BLACK (2025) | G10: RETURN | H10: 46203 | J10: KHALIDA | K10: DA CAMPAIGN | L10: AVAILABLE IN AGENCY | M10: =IF(E10="", "", IF(W10=0, "AVAILABLE", IF(W10 > X10, "LOANED / ON KOL", "AVAILABLE"))) -> LOANED / ON KOL | N10: {=IF(M10="LOANED / ON KOL", INDEX('Step 3 FOC Request'!$G:$G, MATCH(1, ('Step 3 FOC Request'!$A:$A=W10) * ('Step 3 FOC Request'!$F:$F=E10), 0)), "-")} -> Zahral Antika | W10: =MAXIFS('Step 3 FOC Request'!$A:$A, 'Step 3 FOC Request'!$F:$F, $E10) -> 46084.531 | X10: =MAXIFS('Step 4 FOC Return'!$A:$A, 'Step 4 FOC Return'!$E:$E, $E10) -> 0
B11: 46065 | C11: ANNELA | D11: HANDPHONE | E11: 354312420002314 | F11: G-Z-FLIP7 256GB LIGHT GREEN (2025) | G11: RETURN | H11: 46203 | J11: KHALIDA | K11: DA CAMPAIGN | L11: AVAILABLE IN AGENCY | M11: =IF(E11="", "", IF(W11=0, "AVAILABLE", IF(W11 > X11, "LOANED / ON KOL", "AVAILABLE"))) -> LOANED / ON KOL | N11: {=IF(M11="LOANED / ON KOL", INDEX('Step 3 FOC Request'!$G:$G, MATCH(1, ('Step 3 FOC Request'!$A:$A=W11) * ('Step 3 FOC Request'!$F:$F=E11), 0)), "-")} -> Aliya | W11: =MAXIFS('Step 3 FOC Request'!$A:$A, 'Step 3 FOC Request'!$F:$F, $E11) -> 46076.812 | X11: =MAXIFS('Step 4 FOC Return'!$A:$A, 'Step 4 FOC Return'!$E:$E, $E11) -> 0
B12: 46065 | C12: ANNELA | D12: HANDPHONE | E12: 354312420030364 | F12: G-Z-FLIP7 256GB DARK BLUE (2025) | G12: RETURN | H12: 46203 | J12: KHALIDA | K12: DA CAMPAIGN | L12: AVAILABLE IN AGENCY | M12: =IF(E12="", "", IF(W12=0, "AVAILABLE", IF(W12 > X12, "LOANED / ON KOL", "AVAILABLE"))) -> AVAILABLE | N12: {=IF(M12="LOANED / ON KOL", INDEX('Step 3 FOC Request'!$G:$G, MATCH(1, ('Step 3 FOC Request'!$A:$A=W12) * ('Step 3 FOC Request'!$F:$F=E12), 0)), "-")} -> - | W12: =MAXIFS('Step 3 FOC Request'!$A:$A, 'Step 3 FOC Request'!$F:$F, $E12) -> 0 | X12: =MAXIFS('Step 4 FOC Return'!$A:$A, 'Step 4 FOC Return'!$E:$E, $E12) -> 0
B13: 46065 | C13: ANNELA | D13: HANDPHONE | E13: 358410185002861 | F13: G-S25 256GB DARK BLUE(2025) | G13: RETURN | H13: 46203 | J13: KHALIDA | K13: DA CAMPAIGN | L13: AVAILABLE IN AGENCY | M13: =IF(E13="", "", IF(W13=0, "AVAILABLE", IF(W13 > X13, "LOANED / ON KOL", "AVAILABLE"))) -> LOANED / ON KOL | N13: {=IF(M13="LOANED / ON KOL", INDEX('Step 3 FOC Request'!$G:$G, MATCH(1, ('Step 3 FOC Request'!$A:$A=W13) * ('Step 3 FOC Request'!$F:$F=E13), 0)), "-")} -> Adinka | W13: =MAXIFS('Step 3 FOC Request'!$A:$A, 'Step 3 FOC Request'!$F:$F, $E13) -> 46066.589 | X13: =MAXIFS('Step 4 FOC Return'!$A:$A, 'Step 4 FOC Return'!$E:$E, $E13) -> 0
B14: 46065 | C14: ANNELA | D14: HANDPHONE | E14: 358410185073425 | F14: G-S25 256GB SILVER (2025) | G14: RETURN | H14: 46203 | J14: KHALIDA | K14: DA CAMPAIGN | L14: AVAILABLE IN AGENCY | M14: =IF(E14="", "", IF(W14=0, "AVAILABLE", IF(W14 > X14, "LOANED / ON KOL", "AVAILABLE"))) -> LOANED / ON KOL | N14: {=IF(M14="LOANED / ON KOL", INDEX('Step 3 FOC Request'!$G:$G, MATCH(1, ('Step 3 FOC Request'!$A:$A=W14) * ('Step 3 FOC Request'!$F:$F=E14), 0)), "-")} -> Raje | W14: =MAXIFS('Step 3 FOC Request'!$A:$A, 'Step 3 FOC Request'!$F:$F, $E14) -> 46090.563 | X14: =MAXIFS('Step 4 FOC Return'!$A:$A, 'Step 4 FOC Return'!$E:$E, $E14) -> 0
B15: 46065 | C15: ANNELA | D15: HANDPHONE | E15: 358410185074076 | F15: G-S25 256GB SILVER(2025) | G15: RETURN | H15: 46203 | J15: KHALIDA | K15: DA CAMPAIGN | L15: AVAILABLE IN AGENCY | M15: =IF(E15="", "", IF(W15=0, "AVAILABLE", IF(W15 > X15, "LOANED / ON KOL", "AVAILABLE"))) -> LOANED / ON KOL | N15: {=IF(M15="LOANED / ON KOL", INDEX('Step 3 FOC Request'!$G:$G, MATCH(1, ('Step 3 FOC Request'!$A:$A=W15) * ('Step 3 FOC Request'!$F:$F=E15), 0)), "-")} -> Satria | P15: Layar Sudah ada baret dari penerimaan awal | W15: =MAXIFS('Step 3 FOC Request'!$A:$A, 'Step 3 FOC Request'!$F:$F, $E15) -> 46084.58 | X15: =MAXIFS('Step 4 FOC Return'!$A:$A, 'Step 4 FOC Return'!$E:$E, $E15) -> 0
B16: 46065 | C16: AKBARI | D16: TAB | E16: RR2Y900B1ZK | F16: G-TAB-S11 WIFI, GRAY (2025) | G16: RETURN | H16: 46203 | J16: ABIGAIL | K16: S11 Sustence | L16: AVAILABLE IN AGENCY | M16: =IF(E16="", "", IF(W16=0, "AVAILABLE", IF(W16 > X16, "LOANED / ON KOL", "AVAILABLE"))) -> AVAILABLE | N16: {=IF(M16="LOANED / ON KOL", INDEX('Step 3 FOC Request'!$G:$G, MATCH(1, ('Step 3 FOC Request'!$A:$A=W16) * ('Step 3 FOC Request'!$F:$F=E16), 0)), "-")} -> - | W16: =MAXIFS('Step 3 FOC Request'!$A:$A, 'Step 3 FOC Request'!$F:$F, $E16) -> 0 | X16: =MAXIFS('Step 4 FOC Return'!$A:$A, 'Step 4 FOC Return'!$E:$E, $E16) -> 0
B17: 46065 | C17: AKBARI | D17: TAB | E17: RR2Y900APAE | F17: G-TAB-S11 WIFI, GRAY (2025) | G17: RETURN | H17: 46203 | J17: ABIGAIL | K17: S11 Sustence | L17: AVAILABLE IN AGENCY | M17: =IF(E17="", "", IF(W17=0, "AVAILABLE", IF(W17 > X17, "LOANED / ON KOL", "AVAILABLE"))) -> AVAILABLE | N17: {=IF(M17="LOANED / ON KOL", INDEX('Step 3 FOC Request'!$G:$G, MATCH(1, ('Step 3 FOC Request'!$A:$A=W17) * ('Step 3 FOC Request'!$F:$F=E17), 0)), "-")} -> - | W17: =MAXIFS('Step 3 FOC Request'!$A:$A, 'Step 3 FOC Request'!$F:$F, $E17) -> 0 | X17: =MAXIFS('Step 4 FOC Return'!$A:$A, 'Step 4 FOC Return'!$E:$E, $E17) -> 0
B18: 46065 | C18: AKBARI | D18: ACCESORIES | E18: RF7Y9001GSXCIS | F18: ACC HHP, KEYBOARD TAB S11 | G18: RETURN | H18: 46203 | J18: ABIGAIL | K18: S11 Sustence | L18: AVAILABLE IN AGENCY | M18: =IF(E18="", "", IF(W18=0, "AVAILABLE", IF(W18 > X18, "LOANED / ON KOL", "AVAILABLE"))) -> AVAILABLE | N18: {=IF(M18="LOANED / ON KOL", INDEX('Step 3 FOC Request'!$G:$G, MATCH(1, ('Step 3 FOC Request'!$A:$A=W18) * ('Step 3 FOC Request'!$F:$F=E18), 0)), "-")} -> - | W18: =MAXIFS('Step 3 FOC Request'!$A:$A, 'Step 3 FOC Request'!$F:$F, $E18) -> 0 | X18: =MAXIFS('Step 4 FOC Return'!$A:$A, 'Step 4 FOC Return'!$E:$E, $E18) -> 0
B19: 46065 | C19: AKBARI | D19: ACCESORIES | E19: RF7Y9001FKBCIS | F19: ACC HHP, KEYBOARD TAB S11 | G19: RETURN | H19: 46203 | J19: ABIGAIL | K19: S11 Sustence | L19: AVAILABLE IN AGENCY | M19: =IF(E19="", "", IF(W19=0, "AVAILABLE", IF(W19 > X19, "LOANED / ON KOL", "AVAILABLE"))) -> AVAILABLE | N19: {=IF(M19="LOANED / ON KOL", INDEX('Step 3 FOC Request'!$G:$G, MATCH(1, ('Step 3 FOC Request'!$A:$A=W19) * ('Step 3 FOC Request'!$F:$F=E19), 0)), "-")} -> - | W19: =MAXIFS('Step 3 FOC Request'!$A:$A, 'Step 3 FOC Request'!$F:$F, $E19) -> 0 | X19: =MAXIFS('Step 4 FOC Return'!$A:$A, 'Step 4 FOC Return'!$E:$E, $E19) -> 0
B20: 46065 | C20: AKBARI | D20: ACCESORIES | E20: RF7Y9001EJJCIS | F20: ACC HHP, KEYBOARD TAB S11 | G20: RETURN | H20: 46203 | J20: ABIGAIL | K20: S11 Sustence | L20: AVAILABLE IN AGENCY | M20: =IF(E20="", "", IF(W20=0, "AVAILABLE", IF(W20 > X20, "LOANED / ON KOL", "AVAILABLE"))) -> AVAILABLE | N20: {=IF(M20="LOANED / ON KOL", INDEX('Step 3 FOC Request'!$G:$G, MATCH(1, ('Step 3 FOC Request'!$A:$A=W20) * ('Step 3 FOC Request'!$F:$F=E20), 0)), "-")} -> - | W20: =MAXIFS('Step 3 FOC Request'!$A:$A, 'Step 3 FOC Request'!$F:$F, $E20) -> 0 | X20: =MAXIFS('Step 4 FOC Return'!$A:$A, 'Step 4 FOC Return'!$E:$E, $E20) -> 0
B21: 46065 | C21: AKBARI | D21: TAB | E21: 358387120015010 | F21: G-TAB-S11-ULTRA-5G GRAY (2025) | G21: RETURN | H21: 46203 | J21: ABIGAIL | K21: S11 Sustence | L21: AVAILABLE IN AGENCY | M21: =IF(E21="", "", IF(W21=0, "AVAILABLE", IF(W21 > X21, "LOANED / ON KOL", "AVAILABLE"))) -> AVAILABLE | N21: {=IF(M21="LOANED / ON KOL", INDEX('Step 3 FOC Request'!$G:$G, MATCH(1, ('Step 3 FOC Request'!$A:$A=W21) * ('Step 3 FOC Request'!$F:$F=E21), 0)), "-")} -> - | W21: =MAXIFS('Step 3 FOC Request'!$A:$A, 'Step 3 FOC Request'!$F:$F, $E21) -> 0 | X21: =MAXIFS('Step 4 FOC Return'!$A:$A, 'Step 4 FOC Return'!$E:$E, $E21) -> 0
B22: 46065 | C22: AKBARI | D22: TAB | E22: 358387120018311 | F22: G-TAB-S11-ULTRA-5G GRAY (2025) | G22: RETURN | H22: 46203 | J22: ABIGAIL | K22: S11 Sustence | L22: AVAILABLE IN AGENCY | M22: =IF(E22="", "", IF(W22=0, "AVAILABLE", IF(W22 > X22, "LOANED / ON KOL", "AVAILABLE"))) -> AVAILABLE | N22: {=IF(M22="LOANED / ON KOL", INDEX('Step 3 FOC Request'!$G:$G, MATCH(1, ('Step 3 FOC Request'!$A:$A=W22) * ('Step 3 FOC Request'!$F:$F=E22), 0)), "-")} -> - | W22: =MAXIFS('Step 3 FOC Request'!$A:$A, 'Step 3 FOC Request'!$F:$F, $E22) -> 0 | X22: =MAXIFS('Step 4 FOC Return'!$A:$A, 'Step 4 FOC Return'!$E:$E, $E22) -> 0
B23: 46065 | C23: AKBARI | D23: ACCESORIES | E23: RF7Y803MA0VCIS | F23: ACC HHP, KEYBOARD SLIM BLACK, TAB S11 ULTRA | G23: RETURN | H23: 46203 | J23: ABIGAIL | K23: S11 Sustence | L23: AVAILABLE IN AGENCY | M23: =IF(E23="", "", IF(W23=0, "AVAILABLE", IF(W23 > X23, "LOANED / ON KOL", "AVAILABLE"))) -> AVAILABLE | N23: {=IF(M23="LOANED / ON KOL", INDEX('Step 3 FOC Request'!$G:$G, MATCH(1, ('Step 3 FOC Request'!$A:$A=W23) * ('Step 3 FOC Request'!$F:$F=E23), 0)), "-")} -> - | W23: =MAXIFS('Step 3 FOC Request'!$A:$A, 'Step 3 FOC Request'!$F:$F, $E23) -> 0 | X23: =MAXIFS('Step 4 FOC Return'!$A:$A, 'Step 4 FOC Return'!$E:$E, $E23) -> 0
B24: 46065 | C24: AKBARI | D24: ACCESORIES | E24: RF7Y803M3WYCIS | F24: ACC HHP, KEYBOARD SLIM BLACK, TAB S11 ULTRA | G24: RETURN | H24: 46203 | J24: ABIGAIL | K24: S11 Sustence | L24: AVAILABLE IN AGENCY | M24: =IF(E24="", "", IF(W24=0, "AVAILABLE", IF(W24 > X24, "LOANED / ON KOL", "AVAILABLE"))) -> AVAILABLE | N24: {=IF(M24="LOANED / ON KOL", INDEX('Step 3 FOC Request'!$G:$G, MATCH(1, ('Step 3 FOC Request'!$A:$A=W24) * ('Step 3 FOC Request'!$F:$F=E24), 0)), "-")} -> - | W24: =MAXIFS('Step 3 FOC Request'!$A:$A, 'Step 3 FOC Request'!$F:$F, $E24) -> 0 | X24: =MAXIFS('Step 4 FOC Return'!$A:$A, 'Step 4 FOC Return'!$E:$E, $E24) -> 0
B25: 46065 | C25: YAYA | D25: HANDPHONE | E25: 355649780288085 | F25: G-A07-5G 128GB LIGHT VIOLET | G25: RETURN | H25: N/A | J25: TASHYA | L25: AVAILABLE IN AGENCY | M25: =IF(E25="", "", IF(W25=0, "AVAILABLE", IF(W25 > X25, "LOANED / ON KOL", "AVAILABLE"))) -> LOANED / ON KOL | N25: {=IF(M25="LOANED / ON KOL", INDEX('Step 3 FOC Request'!$G:$G, MATCH(1, ('Step 3 FOC Request'!$A:$A=W25) * ('Step 3 FOC Request'!$F:$F=E25), 0)), "-")} -> VINCENT PRATAMA | W25: =MAXIFS('Step 3 FOC Request'!$A:$A, 'Step 3 FOC Request'!$F:$F, $E25) -> 46085.661 | X25: =MAXIFS('Step 4 FOC Return'!$A:$A, 'Step 4 FOC Return'!$E:$E, $E25) -> 0
B26: 46065 | C26: YAYA | D26: HANDPHONE | E26: 355649780142837 | F26: G-A07-5G 128GB LIGHT VIOLET | G26: RETURN | H26: N/A | J26: TASHYA | L26: AVAILABLE IN AGENCY | M26: =IF(E26="", "", IF(W26=0, "AVAILABLE", IF(W26 > X26, "LOANED / ON KOL", "AVAILABLE"))) -> LOANED / ON KOL | N26: {=IF(M26="LOANED / ON KOL", INDEX('Step 3 FOC Request'!$G:$G, MATCH(1, ('Step 3 FOC Request'!$A:$A=W26) * ('Step 3 FOC Request'!$F:$F=E26), 0)), "-")} -> Naqi | W26: =MAXIFS('Step 3 FOC Request'!$A:$A, 'Step 3 FOC Request'!$F:$F, $E26) -> 46086.584 | X26: =MAXIFS('Step 4 FOC Return'!$A:$A, 'Step 4 FOC Return'!$E:$E, $E26) -> 0
B27: 46065 | C27: YAYA | D27: HANDPHONE | E27: 355649780287392 | F27: G-A07-5G 128GB LIGHT VIOLET | G27: RETURN | H27: N/A | J27: TASHYA | L27: AVAILABLE IN AGENCY | M27: =IF(E27="", "", IF(W27=0, "AVAILABLE", IF(W27 > X27, "LOANED / ON KOL", "AVAILABLE"))) -> LOANED / ON KOL | N27: {=IF(M27="LOANED / ON KOL", INDEX('Step 3 FOC Request'!$G:$G, MATCH(1, ('Step 3 FOC Request'!$A:$A=W27) * ('Step 3 FOC Request'!$F:$F=E27), 0)), "-")} -> Farhan Frisia | W27: =MAXIFS('Step 3 FOC Request'!$A:$A, 'Step 3 FOC Request'!$F:$F, $E27) -> 46086.839 | X27: =MAXIFS('Step 4 FOC Return'!$A:$A, 'Step 4 FOC Return'!$E:$E, $E27) -> 0
B28: 46066 | C28: MANDIE | D28: HANDPHONE | E28: 352901540311464 | F28: G-S25-ULTRA WHITE SILVER | G28: RETURN | H28: ASAP | J28: OLIV | K28: RAMADAN CAMPAIGN | L28: AVAILABLE IN AGENCY | M28: =IF(E28="", "", IF(W28=0, "AVAILABLE", IF(W28 > X28, "LOANED / ON KOL", "AVAILABLE"))) -> LOANED / ON KOL | N28: {=IF(M28="LOANED / ON KOL", INDEX('Step 3 FOC Request'!$G:$G, MATCH(1, ('Step 3 FOC Request'!$A:$A=W28) * ('Step 3 FOC Request'!$F:$F=E28), 0)), "-")} -> Shafa Lubis | W28: =MAXIFS('Step 3 FOC Request'!$A:$A, 'Step 3 FOC Request'!$F:$F, $E28) -> 46078.75 | X28: =MAXIFS('Step 4 FOC Return'!$A:$A, 'Step 4 FOC Return'!$E:$E, $E28) -> 0
B29: 46066 | C29: MANDIE | D29: HANDPHONE | E29: 352901540313817 | F29: G-S25-ULTRA GRAY | G29: RETURN | H29: ASAP | J29: OLIV | K29: RAMADAN CAMPAIGN | L29: AVAILABLE IN AGENCY | M29: =IF(E29="", "", IF(W29=0, "AVAILABLE", IF(W29 > X29, "LOANED / ON KOL", "AVAILABLE"))) -> LOANED / ON KOL | N29: {=IF(M29="LOANED / ON KOL", INDEX('Step 3 FOC Request'!$G:$G, MATCH(1, ('Step 3 FOC Request'!$A:$A=W29) * ('Step 3 FOC Request'!$F:$F=E29), 0)), "-")} -> madaryanhadi | W29: =MAXIFS('Step 3 FOC Request'!$A:$A, 'Step 3 FOC Request'!$F:$F, $E29) -> 46090.785 | X29: =MAXIFS('Step 4 FOC Return'!$A:$A, 'Step 4 FOC Return'!$E:$E, $E29) -> 0
B30: 46066 | C30: MANDIE | D30: HANDPHONE | E30: 355626620021892 | F30: G-Z-FOLD7 BLUE SHADOW | G30: RETURN | H30: ASAP | J30: OLIV | K30: RAMADAN CAMPAIGN | L30: AVAILABLE IN AGENCY | M30: =IF(E30="", "", IF(W30=0, "AVAILABLE", IF(W30 > X30, "LOANED / ON KOL", "AVAILABLE"))) -> LOANED / ON KOL | N30: {=IF(M30="LOANED / ON KOL", INDEX('Step 3 FOC Request'!$G:$G, MATCH(1, ('Step 3 FOC Request'!$A:$A=W30) * ('Step 3 FOC Request'!$F:$F=E30), 0)), "-")} -> Apip | W30: =MAXIFS('Step 3 FOC Request'!$A:$A, 'Step 3 FOC Request'!$F:$F, $E30) -> 46078.75 | X30: =MAXIFS('Step 4 FOC Return'!$A:$A, 'Step 4 FOC Return'!$E:$E, $E30) -> 0
B31: 46066 | C31: MANDIE | D31: HANDPHONE | E31: 354312420000599 | F31: G-Z-FLIP7 JETBLACK | G31: RETURN | H31: ASAP | J31: OLIV | K31: RAMADAN CAMPAIGN | L31: AVAILABLE IN AGENCY | M31: =IF(E31="", "", IF(W31=0, "AVAILABLE", IF(W31 > X31, "LOANED / ON KOL", "AVAILABLE"))) -> LOANED / ON KOL | N31: {=IF(M31="LOANED / ON KOL", INDEX('Step 3 FOC Request'!$G:$G, MATCH(1, ('Step 3 FOC Request'!$A:$A=W31) * ('Step 3 FOC Request'!$F:$F=E31), 0)), "-")} -> DRG Nurina | W31: =MAXIFS('Step 3 FOC Request'!$A:$A, 'Step 3 FOC Request'!$F:$F, $E31) -> 46080.555 | X31: =MAXIFS('Step 4 FOC Return'!$A:$A, 'Step 4 FOC Return'!$E:$E, $E31) -> 0
B32: 46066 | C32: YAYA | D32: HANDPHONE | E32: 355500722565579 | F32: G-A-175LTE LIGHT BLUE RAMADAN PACKAGE | G32: RETURN | H32: 46172 | J32: TASHYA | L32: AVAILABLE IN AGENCY | M32: =IF(E32="", "", IF(W32=0, "AVAILABLE", IF(W32 > X32, "LOANED / ON KOL", "AVAILABLE"))) -> LOANED / ON KOL | N32: {=IF(M32="LOANED / ON KOL", INDEX('Step 3 FOC Request'!$G:$G, MATCH(1, ('Step 3 FOC Request'!$A:$A=W32) * ('Step 3 FOC Request'!$F:$F=E32), 0)), "-")} -> MEIRANI AMALIA | W32: =MAXIFS('Step 3 FOC Request'!$A:$A, 'Step 3 FOC Request'!$F:$F, $E32) -> 46073.454 | X32: =MAXIFS('Step 4 FOC Return'!$A:$A, 'Step 4 FOC Return'!$E:$E, $E32) -> 0
B33: 46066 | C33: YAYA | D33: HANDPHONE | E33: 355500722520517 | F33: G-A-175LTE BLACK RAMADAM PACKAGE | G33: RETURN | H33: 46172 | J33: TASHYA | L33: AVAILABLE IN AGENCY | M33: =IF(E33="", "", IF(W33=0, "AVAILABLE", IF(W33 > X33, "LOANED / ON KOL", "AVAILABLE"))) -> LOANED / ON KOL | N33: {=IF(M33="LOANED / ON KOL", INDEX('Step 3 FOC Request'!$G:$G, MATCH(1, ('Step 3 FOC Request'!$A:$A=W33) * ('Step 3 FOC Request'!$F:$F=E33), 0)), "-")} -> Cex Daniel | W33: =MAXIFS('Step 3 FOC Request'!$A:$A, 'Step 3 FOC Request'!$F:$F, $E33) -> 46077.748 | X33: =MAXIFS('Step 4 FOC Return'!$A:$A, 'Step 4 FOC Return'!$E:$E, $E33) -> 0
B34: 46066 | C34: YAYA | D34: HANDPHONE | E34: 355500722567443 | F34: G-A-175LTE LIGHT BLUE PACKAGE | G34: RETURN | H34: 46172 | J34: TASHYA | L34: AVAILABLE IN AGENCY | M34: =IF(E34="", "", IF(W34=0, "AVAILABLE", IF(W34 > X34, "LOANED / ON KOL", "AVAILABLE"))) -> LOANED / ON KOL | N34: {=IF(M34="LOANED / ON KOL", INDEX('Step 3 FOC Request'!$G:$G, MATCH(1, ('Step 3 FOC Request'!$A:$A=W34) * ('Step 3 FOC Request'!$F:$F=E34), 0)), "-")} -> RAUDAH | W34: =MAXIFS('Step 3 FOC Request'!$A:$A, 'Step 3 FOC Request'!$F:$F, $E34) -> 46078.513 | X34: =MAXIFS('Step 4 FOC Return'!$A:$A, 'Step 4 FOC Return'!$E:$E, $E34) -> 0
B35: 46071 | D35: HANDPHONE | E35: 350009210308596 | F35: G-S24-FE 256GB GRAY | L35: AVAILABLE IN AGENCY | M35: =IF(E35="", "", IF(W35=0, "AVAILABLE", IF(W35 > X35, "LOANED / ON KOL", "AVAILABLE"))) -> AVAILABLE | N35: {=IF(M35="LOANED / ON KOL", INDEX('Step 3 FOC Request'!$G:$G, MATCH(1, ('Step 3 FOC Request'!$A:$A=W35) * ('Step 3 FOC Request'!$F:$F=E35), 0)), "-")} -> - | W35: =MAXIFS('Step 3 FOC Request'!$A:$A, 'Step 3 FOC Request'!$F:$F, $E35) -> 0 | X35: =MAXIFS('Step 4 FOC Return'!$A:$A, 'Step 4 FOC Return'!$E:$E, $E35) -> 0
B36: 46071 | D36: HANDPHONE | E36: 350009210289044 | F36: G-S24-FE 256GB GRAY | L36: AVAILABLE IN AGENCY | M36: =IF(E36="", "", IF(W36=0, "AVAILABLE", IF(W36 > X36, "LOANED / ON KOL", "AVAILABLE"))) -> AVAILABLE | N36: {=IF(M36="LOANED / ON KOL", INDEX('Step 3 FOC Request'!$G:$G, MATCH(1, ('Step 3 FOC Request'!$A:$A=W36) * ('Step 3 FOC Request'!$F:$F=E36), 0)), "-")} -> - | W36: =MAXIFS('Step 3 FOC Request'!$A:$A, 'Step 3 FOC Request'!$F:$F, $E36) -> 0 | X36: =MAXIFS('Step 4 FOC Return'!$A:$A, 'Step 4 FOC Return'!$E:$E, $E36) -> 0
B37: 46071 | D37: HANDPHONE | E37: 350009210308232 | F37: G-S24-FE 256GB GRAY | L37: AVAILABLE IN AGENCY | M37: =IF(E37="", "", IF(W37=0, "AVAILABLE", IF(W37 > X37, "LOANED / ON KOL", "AVAILABLE"))) -> AVAILABLE | N37: {=IF(M37="LOANED / ON KOL", INDEX('Step 3 FOC Request'!$G:$G, MATCH(1, ('Step 3 FOC Request'!$A:$A=W37) * ('Step 3 FOC Request'!$F:$F=E37), 0)), "-")} -> - | W37: =MAXIFS('Step 3 FOC Request'!$A:$A, 'Step 3 FOC Request'!$F:$F, $E37) -> 0 | X37: =MAXIFS('Step 4 FOC Return'!$A:$A, 'Step 4 FOC Return'!$E:$E, $E37) -> 0
B38: 46071 | D38: HANDPHONE | E38: 350009210074339 | F38: G-S24-FE 256GB GRAPHITE | G38: RETURN | J38: SALMA | L38: AVAILABLE IN AGENCY | M38: =IF(E38="", "", IF(W38=0, "AVAILABLE", IF(W38 > X38, "LOANED / ON KOL", "AVAILABLE"))) -> AVAILABLE | N38: {=IF(M38="LOANED / ON KOL", INDEX('Step 3 FOC Request'!$G:$G, MATCH(1, ('Step 3 FOC Request'!$A:$A=W38) * ('Step 3 FOC Request'!$F:$F=E38), 0)), "-")} -> - | W38: =MAXIFS('Step 3 FOC Request'!$A:$A, 'Step 3 FOC Request'!$F:$F, $E38) -> 0 | X38: =MAXIFS('Step 4 FOC Return'!$A:$A, 'Step 4 FOC Return'!$E:$E, $E38) -> 0
B39: 46071 | D39: HANDPHONE | E39: 354922130012054 | F39: G-S25-EDGE 256GB SILVER | J39: TASHYA | L39: AVAILABLE IN AGENCY | M39: =IF(E39="", "", IF(W39=0, "AVAILABLE", IF(W39 > X39, "LOANED / ON KOL", "AVAILABLE"))) -> LOANED / ON KOL | N39: {=IF(M39="LOANED / ON KOL", INDEX('Step 3 FOC Request'!$G:$G, MATCH(1, ('Step 3 FOC Request'!$A:$A=W39) * ('Step 3 FOC Request'!$F:$F=E39), 0)), "-")} -> Jevin Julian | W39: =MAXIFS('Step 3 FOC Request'!$A:$A, 'Step 3 FOC Request'!$F:$F, $E39) -> 46085.693 | X39: =MAXIFS('Step 4 FOC Return'!$A:$A, 'Step 4 FOC Return'!$E:$E, $E39) -> 0
B40: 46071 | D40: HANDPHONE | E40: 354922130002634 | F40: G-S25-EDGE 256GB JETBLACK | G40: UNRETURN | J40: MARTIN | L40: AVAILABLE IN AGENCY | M40: =IF(E40="", "", IF(W40=0, "AVAILABLE", IF(W40 > X40, "LOANED / ON KOL", "AVAILABLE"))) -> AVAILABLE | N40: {=IF(M40="LOANED / ON KOL", INDEX('Step 3 FOC Request'!$G:$G, MATCH(1, ('Step 3 FOC Request'!$A:$A=W40) * ('Step 3 FOC Request'!$F:$F=E40), 0)), "-")} -> - | W40: =MAXIFS('Step 3 FOC Request'!$A:$A, 'Step 3 FOC Request'!$F:$F, $E40) -> 0 | X40: =MAXIFS('Step 4 FOC Return'!$A:$A, 'Step 4 FOC Return'!$E:$E, $E40) -> 0
...

Sheet Step 2.1 FOC Return
B1: =IFERROR(__xludf.DUMMYFUNCTION("QUERY('Step 1 Data Bank'!B:P, ""SELECT * WHERE G = 'RETURN'"", 1) "),"DATE OF RECEIPT") -> DATE OF RECEIPT | C1: =IFERROR(__xludf.DUMMYFUNCTION("""COMPUTED_VALUE"""),"SEIN PIC NAME") -> SEIN PIC NAME | D1: =IFERROR(__xludf.DUMMYFUNCTION("""COMPUTED_VALUE"""),"FOC TYPE") -> FOC TYPE | E1: =IFERROR(__xludf.DUMMYFUNCTION("""COMPUTED_VALUE"""),"SERIAL NUMBER (IMEI/SN)") -> SERIAL NUMBER (IMEI/SN) | F1: =IFERROR(__xludf.DUMMYFUNCTION("""COMPUTED_VALUE"""),"UNIT NAME") -> UNIT NAME | G1: =IFERROR(__xludf.DUMMYFUNCTION("""COMPUTED_VALUE"""),"FOC STATUS") -> FOC STATUS | H1: =IFERROR(__xludf.DUMMYFUNCTION("""COMPUTED_VALUE"""),"PLANNED RETURN DATE") -> PLANNED RETURN DATE | I1: =IFERROR(__xludf.DUMMYFUNCTION("""COMPUTED_VALUE"""),"RECEIVED DATE TIME STAMP (LINK)") -> RECEIVED DATE TIME STAMP (LINK) | J1: =IFERROR(__xludf.DUMMYFUNCTION("""COMPUTED_VALUE"""),"GOAT PIC (PLANNER)") -> GOAT PIC (PLANNER) | K1: =IFERROR(__xludf.DUMMYFUNCTION("""COMPUTED_VALUE"""),"CAMPAIGN NAME") -> CAMPAIGN NAME | L1: =IFERROR(__xludf.DUMMYFUNCTION("""COMPUTED_VALUE"""),"STATUS") -> STATUS | M1: =IFERROR(__xludf.DUMMYFUNCTION("""COMPUTED_VALUE"""),"STATUS LOCATION") -> STATUS LOCATION | N1: =IFERROR(__xludf.DUMMYFUNCTION("""COMPUTED_VALUE"""),"ON HOLDER") -> ON HOLDER | O1: =IFERROR(__xludf.DUMMYFUNCTION("""COMPUTED_VALUE"""),"RETURN TO TCC RECEIPT (LINK)") -> RETURN TO TCC RECEIPT (LINK) | P1: =IFERROR(__xludf.DUMMYFUNCTION("""COMPUTED_VALUE"""),"COMMENTS") -> COMMENTS
B2: =IFERROR(__xludf.DUMMYFUNCTION("""COMPUTED_VALUE"""),46065.0) -> 46065 | C2: =IFERROR(__xludf.DUMMYFUNCTION("""COMPUTED_VALUE"""),"YAYA") -> YAYA | D2: =IFERROR(__xludf.DUMMYFUNCTION("""COMPUTED_VALUE"""),"HANDPHONE") -> HANDPHONE | E2: =IFERROR(__xludf.DUMMYFUNCTION("""COMPUTED_VALUE"""),3.51225503076083E14) -> 351225503076083 | F2: =IFERROR(__xludf.DUMMYFUNCTION("""COMPUTED_VALUE"""),"G-A07 RAMADHAN PACKAGE") -> G-A07 RAMADHAN PACKAGE | G2: =IFERROR(__xludf.DUMMYFUNCTION("""COMPUTED_VALUE"""),"RETURN") -> RETURN | H2: =IFERROR(__xludf.DUMMYFUNCTION("""COMPUTED_VALUE"""),46172.0) -> 46172 | J2: =IFERROR(__xludf.DUMMYFUNCTION("""COMPUTED_VALUE"""),"TASHYA") -> TASHYA | L2: =IFERROR(__xludf.DUMMYFUNCTION("""COMPUTED_VALUE"""),"AVAILABLE IN AGENCY") -> AVAILABLE IN AGENCY | M2: =IFERROR(__xludf.DUMMYFUNCTION("""COMPUTED_VALUE"""),"LOANED / ON KOL") -> LOANED / ON KOL | N2: =IFERROR(__xludf.DUMMYFUNCTION("""COMPUTED_VALUE"""),"Mushdalifah ( Aman)") -> Mushdalifah ( Aman)
B3: =IFERROR(__xludf.DUMMYFUNCTION("""COMPUTED_VALUE"""),46065.0) -> 46065 | C3: =IFERROR(__xludf.DUMMYFUNCTION("""COMPUTED_VALUE"""),"YAYA") -> YAYA | D3: =IFERROR(__xludf.DUMMYFUNCTION("""COMPUTED_VALUE"""),"HANDPHONE") -> HANDPHONE | E3: =IFERROR(__xludf.DUMMYFUNCTION("""COMPUTED_VALUE"""),3.51225503087627E14) -> 351225503087627 | F3: =IFERROR(__xludf.DUMMYFUNCTION("""COMPUTED_VALUE"""),"G-A07 RAMADHAN PACKAGE") -> G-A07 RAMADHAN PACKAGE | G3: =IFERROR(__xludf.DUMMYFUNCTION("""COMPUTED_VALUE"""),"RETURN") -> RETURN | H3: =IFERROR(__xludf.DUMMYFUNCTION("""COMPUTED_VALUE"""),46172.0) -> 46172 | J3: =IFERROR(__xludf.DUMMYFUNCTION("""COMPUTED_VALUE"""),"TASHYA") -> TASHYA | L3: =IFERROR(__xludf.DUMMYFUNCTION("""COMPUTED_VALUE"""),"AVAILABLE IN AGENCY") -> AVAILABLE IN AGENCY | M3: =IFERROR(__xludf.DUMMYFUNCTION("""COMPUTED_VALUE"""),"LOANED / ON KOL") -> LOANED / ON KOL | N3: =IFERROR(__xludf.DUMMYFUNCTION("""COMPUTED_VALUE"""),"AMHAD FADHILLA") -> AMHAD FADHILLA
B4: =IFERROR(__xludf.DUMMYFUNCTION("""COMPUTED_VALUE"""),46065.0) -> 46065 | C4: =IFERROR(__xludf.DUMMYFUNCTION("""COMPUTED_VALUE"""),"YAYA") -> YAYA | D4: =IFERROR(__xludf.DUMMYFUNCTION("""COMPUTED_VALUE"""),"HANDPHONE") -> HANDPHONE | E4: =IFERROR(__xludf.DUMMYFUNCTION("""COMPUTED_VALUE"""),3.51225503088054E14) -> 351225503088054 | F4: =IFERROR(__xludf.DUMMYFUNCTION("""COMPUTED_VALUE"""),"G-A07 RAMADHAN PACKAGE") -> G-A07 RAMADHAN PACKAGE | G4: =IFERROR(__xludf.DUMMYFUNCTION("""COMPUTED_VALUE"""),"RETURN") -> RETURN | H4: =IFERROR(__xludf.DUMMYFUNCTION("""COMPUTED_VALUE"""),46172.0) -> 46172 | J4: =IFERROR(__xludf.DUMMYFUNCTION("""COMPUTED_VALUE"""),"TASHYA") -> TASHYA | L4: =IFERROR(__xludf.DUMMYFUNCTION("""COMPUTED_VALUE"""),"AVAILABLE IN AGENCY") -> AVAILABLE IN AGENCY | M4: =IFERROR(__xludf.DUMMYFUNCTION("""COMPUTED_VALUE"""),"AVAILABLE") -> AVAILABLE | N4: =IFERROR(__xludf.DUMMYFUNCTION("""COMPUTED_VALUE"""),"-") -> -
B5: =IFERROR(__xludf.DUMMYFUNCTION("""COMPUTED_VALUE"""),46065.0) -> 46065 | C5: =IFERROR(__xludf.DUMMYFUNCTION("""COMPUTED_VALUE"""),"YAYA") -> YAYA | D5: =IFERROR(__xludf.DUMMYFUNCTION("""COMPUTED_VALUE"""),"HANDPHONE") -> HANDPHONE | E5: =IFERROR(__xludf.DUMMYFUNCTION("""COMPUTED_VALUE"""),3.51225503077255E14) -> 351225503077255 | F5: =IFERROR(__xludf.DUMMYFUNCTION("""COMPUTED_VALUE"""),"G-A07 RAMADHAN PACKAGE") -> G-A07 RAMADHAN PACKAGE | G5: =IFERROR(__xludf.DUMMYFUNCTION("""COMPUTED_VALUE"""),"RETURN") -> RETURN | H5: =IFERROR(__xludf.DUMMYFUNCTION("""COMPUTED_VALUE"""),46172.0) -> 46172 | J5: =IFERROR(__xludf.DUMMYFUNCTION("""COMPUTED_VALUE"""),"TASHYA") -> TASHYA | L5: =IFERROR(__xludf.DUMMYFUNCTION("""COMPUTED_VALUE"""),"AVAILABLE IN AGENCY") -> AVAILABLE IN AGENCY | M5: =IFERROR(__xludf.DUMMYFUNCTION("""COMPUTED_VALUE"""),"LOANED / ON KOL") -> LOANED / ON KOL | N5: =IFERROR(__xludf.DUMMYFUNCTION("""COMPUTED_VALUE"""),"Helin Alvia") -> Helin Alvia
B6: =IFERROR(__xludf.DUMMYFUNCTION("""COMPUTED_VALUE"""),46065.0) -> 46065 | C6: =IFERROR(__xludf.DUMMYFUNCTION("""COMPUTED_VALUE"""),"YAYA") -> YAYA | D6: =IFERROR(__xludf.DUMMYFUNCTION("""COMPUTED_VALUE"""),"BUDS") -> BUDS | F6: =IFERROR(__xludf.DUMMYFUNCTION("""COMPUTED_VALUE"""),"G-BUDS4-PRO GOLD (2026)") -> G-BUDS4-PRO GOLD (2026) | G6: =IFERROR(__xludf.DUMMYFUNCTION("""COMPUTED_VALUE"""),"RETURN") -> RETURN | H6: =IFERROR(__xludf.DUMMYFUNCTION("""COMPUTED_VALUE"""),46203.0) -> 46203 | J6: =IFERROR(__xludf.DUMMYFUNCTION("""COMPUTED_VALUE"""),"ABIGAIL") -> ABIGAIL | K6: =IFERROR(__xludf.DUMMYFUNCTION("""COMPUTED_VALUE"""),"Galaxy Buds4 Launch") -> Galaxy Buds4 Launch | L6: =IFERROR(__xludf.DUMMYFUNCTION("""COMPUTED_VALUE"""),"AVAILABLE IN AGENCY") -> AVAILABLE IN AGENCY | M6: =IFERROR(__xludf.DUMMYFUNCTION("""COMPUTED_VALUE"""),"LOANED / ON KOL") -> LOANED / ON KOL | N6: =IFERROR(__xludf.DUMMYFUNCTION("""COMPUTED_VALUE"""),"Jeffry Reksa") -> Jeffry Reksa
B7: =IFERROR(__xludf.DUMMYFUNCTION("""COMPUTED_VALUE"""),46065.0) -> 46065 | C7: =IFERROR(__xludf.DUMMYFUNCTION("""COMPUTED_VALUE"""),"YAYA") -> YAYA | D7: =IFERROR(__xludf.DUMMYFUNCTION("""COMPUTED_VALUE"""),"BUDS") -> BUDS | F7: =IFERROR(__xludf.DUMMYFUNCTION("""COMPUTED_VALUE"""),"G-BUDS4-PRO GOLD (2026)") -> G-BUDS4-PRO GOLD (2026) | G7: =IFERROR(__xludf.DUMMYFUNCTION("""COMPUTED_VALUE"""),"RETURN") -> RETURN | H7: =IFERROR(__xludf.DUMMYFUNCTION("""COMPUTED_VALUE"""),46203.0) -> 46203 | J7: =IFERROR(__xludf.DUMMYFUNCTION("""COMPUTED_VALUE"""),"ABIGAIL") -> ABIGAIL | K7: =IFERROR(__xludf.DUMMYFUNCTION("""COMPUTED_VALUE"""),"Galaxy Buds4 Launch") -> Galaxy Buds4 Launch | L7: =IFERROR(__xludf.DUMMYFUNCTION("""COMPUTED_VALUE"""),"AVAILABLE IN AGENCY") -> AVAILABLE IN AGENCY | M7: =IFERROR(__xludf.DUMMYFUNCTION("""COMPUTED_VALUE"""),"LOANED / ON KOL") -> LOANED / ON KOL | N7: =IFERROR(__xludf.DUMMYFUNCTION("""COMPUTED_VALUE"""),"Maysha Juan") -> Maysha Juan
B8: =IFERROR(__xludf.DUMMYFUNCTION("""COMPUTED_VALUE"""),46065.0) -> 46065 | C8: =IFERROR(__xludf.DUMMYFUNCTION("""COMPUTED_VALUE"""),"YAYA") -> YAYA | D8: =IFERROR(__xludf.DUMMYFUNCTION("""COMPUTED_VALUE"""),"BUDS") -> BUDS | F8: =IFERROR(__xludf.DUMMYFUNCTION("""COMPUTED_VALUE"""),"G-BUDS4-PRO WHITE (2026)") -> G-BUDS4-PRO WHITE (2026) | G8: =IFERROR(__xludf.DUMMYFUNCTION("""COMPUTED_VALUE"""),"RETURN") -> RETURN | H8: =IFERROR(__xludf.DUMMYFUNCTION("""COMPUTED_VALUE"""),46203.0) -> 46203 | J8: =IFERROR(__xludf.DUMMYFUNCTION("""COMPUTED_VALUE"""),"ABIGAIL") -> ABIGAIL | K8: =IFERROR(__xludf.DUMMYFUNCTION("""COMPUTED_VALUE"""),"Galaxy Buds4 Launch") -> Galaxy Buds4 Launch | L8: =IFERROR(__xludf.DUMMYFUNCTION("""COMPUTED_VALUE"""),"AVAILABLE IN AGENCY") -> AVAILABLE IN AGENCY | M8: =IFERROR(__xludf.DUMMYFUNCTION("""COMPUTED_VALUE"""),"LOANED / ON KOL") -> LOANED / ON KOL | N8: =IFERROR(__xludf.DUMMYFUNCTION("""COMPUTED_VALUE"""),"Jevin Julian") -> Jevin Julian
B9: =IFERROR(__xludf.DUMMYFUNCTION("""COMPUTED_VALUE"""),46065.0) -> 46065 | C9: =IFERROR(__xludf.DUMMYFUNCTION("""COMPUTED_VALUE"""),"YAYA") -> YAYA | D9: =IFERROR(__xludf.DUMMYFUNCTION("""COMPUTED_VALUE"""),"BUDS") -> BUDS | F9: =IFERROR(__xludf.DUMMYFUNCTION("""COMPUTED_VALUE"""),"G-BUDS4-PRO WHITE (2026)") -> G-BUDS4-PRO WHITE (2026) | G9: =IFERROR(__xludf.DUMMYFUNCTION("""COMPUTED_VALUE"""),"RETURN") -> RETURN | H9: =IFERROR(__xludf.DUMMYFUNCTION("""COMPUTED_VALUE"""),46203.0) -> 46203 | J9: =IFERROR(__xludf.DUMMYFUNCTION("""COMPUTED_VALUE"""),"ABIGAIL") -> ABIGAIL | K9: =IFERROR(__xludf.DUMMYFUNCTION("""COMPUTED_VALUE"""),"Galaxy Buds4 Launch") -> Galaxy Buds4 Launch | L9: =IFERROR(__xludf.DUMMYFUNCTION("""COMPUTED_VALUE"""),"AVAILABLE IN AGENCY") -> AVAILABLE IN AGENCY | M9: =IFERROR(__xludf.DUMMYFUNCTION("""COMPUTED_VALUE"""),"LOANED / ON KOL") -> LOANED / ON KOL | N9: =IFERROR(__xludf.DUMMYFUNCTION("""COMPUTED_VALUE"""),"Naura Ayu") -> Naura Ayu
B10: =IFERROR(__xludf.DUMMYFUNCTION("""COMPUTED_VALUE"""),46065.0) -> 46065 | C10: =IFERROR(__xludf.DUMMYFUNCTION("""COMPUTED_VALUE"""),"ANNELA") -> ANNELA | D10: =IFERROR(__xludf.DUMMYFUNCTION("""COMPUTED_VALUE"""),"HANDPHONE") -> HANDPHONE | E10: =IFERROR(__xludf.DUMMYFUNCTION("""COMPUTED_VALUE"""),3.54312420000854E14) -> 354312420000854 | F10: =IFERROR(__xludf.DUMMYFUNCTION("""COMPUTED_VALUE"""),"G-Z-FLIP7 256GB BLACK (2025)") -> G-Z-FLIP7 256GB BLACK (2025) | G10: =IFERROR(__xludf.DUMMYFUNCTION("""COMPUTED_VALUE"""),"RETURN") -> RETURN | H10: =IFERROR(__xludf.DUMMYFUNCTION("""COMPUTED_VALUE"""),46203.0) -> 46203 | J10: =IFERROR(__xludf.DUMMYFUNCTION("""COMPUTED_VALUE"""),"KHALIDA") -> KHALIDA | K10: =IFERROR(__xludf.DUMMYFUNCTION("""COMPUTED_VALUE"""),"DA CAMPAIGN") -> DA CAMPAIGN | L10: =IFERROR(__xludf.DUMMYFUNCTION("""COMPUTED_VALUE"""),"AVAILABLE IN AGENCY") -> AVAILABLE IN AGENCY | M10: =IFERROR(__xludf.DUMMYFUNCTION("""COMPUTED_VALUE"""),"LOANED / ON KOL") -> LOANED / ON KOL | N10: =IFERROR(__xludf.DUMMYFUNCTION("""COMPUTED_VALUE"""),"Zahral Antika") -> Zahral Antika
B11: =IFERROR(__xludf.DUMMYFUNCTION("""COMPUTED_VALUE"""),46065.0) -> 46065 | C11: =IFERROR(__xludf.DUMMYFUNCTION("""COMPUTED_VALUE"""),"ANNELA") -> ANNELA | D11: =IFERROR(__xludf.DUMMYFUNCTION("""COMPUTED_VALUE"""),"HANDPHONE") -> HANDPHONE | E11: =IFERROR(__xludf.DUMMYFUNCTION("""COMPUTED_VALUE"""),3.54312420002314E14) -> 354312420002314 | F11: =IFERROR(__xludf.DUMMYFUNCTION("""COMPUTED_VALUE"""),"G-Z-FLIP7 256GB LIGHT GREEN (2025)") -> G-Z-FLIP7 256GB LIGHT GREEN (2025) | G11: =IFERROR(__xludf.DUMMYFUNCTION("""COMPUTED_VALUE"""),"RETURN") -> RETURN | H11: =IFERROR(__xludf.DUMMYFUNCTION("""COMPUTED_VALUE"""),46203.0) -> 46203 | J11: =IFERROR(__xludf.DUMMYFUNCTION("""COMPUTED_VALUE"""),"KHALIDA") -> KHALIDA | K11: =IFERROR(__xludf.DUMMYFUNCTION("""COMPUTED_VALUE"""),"DA CAMPAIGN") -> DA CAMPAIGN | L11: =IFERROR(__xludf.DUMMYFUNCTION("""COMPUTED_VALUE"""),"AVAILABLE IN AGENCY") -> AVAILABLE IN AGENCY | M11: =IFERROR(__xludf.DUMMYFUNCTION("""COMPUTED_VALUE"""),"LOANED / ON KOL") -> LOANED / ON KOL | N11: =IFERROR(__xludf.DUMMYFUNCTION("""COMPUTED_VALUE"""),"Aliya") -> Aliya
B12: =IFERROR(__xludf.DUMMYFUNCTION("""COMPUTED_VALUE"""),46065.0) -> 46065 | C12: =IFERROR(__xludf.DUMMYFUNCTION("""COMPUTED_VALUE"""),"ANNELA") -> ANNELA | D12: =IFERROR(__xludf.DUMMYFUNCTION("""COMPUTED_VALUE"""),"HANDPHONE") -> HANDPHONE | E12: =IFERROR(__xludf.DUMMYFUNCTION("""COMPUTED_VALUE"""),3.54312420030364E14) -> 354312420030364 | F12: =IFERROR(__xludf.DUMMYFUNCTION("""COMPUTED_VALUE"""),"G-Z-FLIP7 256GB DARK BLUE (2025)") -> G-Z-FLIP7 256GB DARK BLUE (2025) | G12: =IFERROR(__xludf.DUMMYFUNCTION("""COMPUTED_VALUE"""),"RETURN") -> RETURN | H12: =IFERROR(__xludf.DUMMYFUNCTION("""COMPUTED_VALUE"""),46203.0) -> 46203 | J12: =IFERROR(__xludf.DUMMYFUNCTION("""COMPUTED_VALUE"""),"KHALIDA") -> KHALIDA | K12: =IFERROR(__xludf.DUMMYFUNCTION("""COMPUTED_VALUE"""),"DA CAMPAIGN") -> DA CAMPAIGN | L12: =IFERROR(__xludf.DUMMYFUNCTION("""COMPUTED_VALUE"""),"AVAILABLE IN AGENCY") -> AVAILABLE IN AGENCY | M12: =IFERROR(__xludf.DUMMYFUNCTION("""COMPUTED_VALUE"""),"AVAILABLE") -> AVAILABLE | N12: =IFERROR(__xludf.DUMMYFUNCTION("""COMPUTED_VALUE"""),"-") -> -
B13: =IFERROR(__xludf.DUMMYFUNCTION("""COMPUTED_VALUE"""),46065.0) -> 46065 | C13: =IFERROR(__xludf.DUMMYFUNCTION("""COMPUTED_VALUE"""),"ANNELA") -> ANNELA | D13: =IFERROR(__xludf.DUMMYFUNCTION("""COMPUTED_VALUE"""),"HANDPHONE") -> HANDPHONE | E13: =IFERROR(__xludf.DUMMYFUNCTION("""COMPUTED_VALUE"""),3.58410185002861E14) -> 358410185002861 | F13: =IFERROR(__xludf.DUMMYFUNCTION("""COMPUTED_VALUE"""),"G-S25 256GB DARK BLUE(2025)") -> G-S25 256GB DARK BLUE(2025) | G13: =IFERROR(__xludf.DUMMYFUNCTION("""COMPUTED_VALUE"""),"RETURN") -> RETURN | H13: =IFERROR(__xludf.DUMMYFUNCTION("""COMPUTED_VALUE"""),46203.0) -> 46203 | J13: =IFERROR(__xludf.DUMMYFUNCTION("""COMPUTED_VALUE"""),"KHALIDA") -> KHALIDA | K13: =IFERROR(__xludf.DUMMYFUNCTION("""COMPUTED_VALUE"""),"DA CAMPAIGN") -> DA CAMPAIGN | L13: =IFERROR(__xludf.DUMMYFUNCTION("""COMPUTED_VALUE"""),"AVAILABLE IN AGENCY") -> AVAILABLE IN AGENCY | M13: =IFERROR(__xludf.DUMMYFUNCTION("""COMPUTED_VALUE"""),"LOANED / ON KOL") -> LOANED / ON KOL | N13: =IFERROR(__xludf.DUMMYFUNCTION("""COMPUTED_VALUE"""),"Adinka") -> Adinka
B14: =IFERROR(__xludf.DUMMYFUNCTION("""COMPUTED_VALUE"""),46065.0) -> 46065 | C14: =IFERROR(__xludf.DUMMYFUNCTION("""COMPUTED_VALUE"""),"ANNELA") -> ANNELA | D14: =IFERROR(__xludf.DUMMYFUNCTION("""COMPUTED_VALUE"""),"HANDPHONE") -> HANDPHONE | E14: =IFERROR(__xludf.DUMMYFUNCTION("""COMPUTED_VALUE"""),3.58410185073425E14) -> 358410185073425 | F14: =IFERROR(__xludf.DUMMYFUNCTION("""COMPUTED_VALUE"""),"G-S25 256GB SILVER (2025)") -> G-S25 256GB SILVER (2025) | G14: =IFERROR(__xludf.DUMMYFUNCTION("""COMPUTED_VALUE"""),"RETURN") -> RETURN | H14: =IFERROR(__xludf.DUMMYFUNCTION("""COMPUTED_VALUE"""),46203.0) -> 46203 | J14: =IFERROR(__xludf.DUMMYFUNCTION("""COMPUTED_VALUE"""),"KHALIDA") -> KHALIDA | K14: =IFERROR(__xludf.DUMMYFUNCTION("""COMPUTED_VALUE"""),"DA CAMPAIGN") -> DA CAMPAIGN | L14: =IFERROR(__xludf.DUMMYFUNCTION("""COMPUTED_VALUE"""),"AVAILABLE IN AGENCY") -> AVAILABLE IN AGENCY | M14: =IFERROR(__xludf.DUMMYFUNCTION("""COMPUTED_VALUE"""),"LOANED / ON KOL") -> LOANED / ON KOL | N14: =IFERROR(__xludf.DUMMYFUNCTION("""COMPUTED_VALUE"""),"Raje") -> Raje
B15: =IFERROR(__xludf.DUMMYFUNCTION("""COMPUTED_VALUE"""),46065.0) -> 46065 | C15: =IFERROR(__xludf.DUMMYFUNCTION("""COMPUTED_VALUE"""),"ANNELA") -> ANNELA | D15: =IFERROR(__xludf.DUMMYFUNCTION("""COMPUTED_VALUE"""),"HANDPHONE") -> HANDPHONE | E15: =IFERROR(__xludf.DUMMYFUNCTION("""COMPUTED_VALUE"""),3.58410185074076E14) -> 358410185074076 | F15: =IFERROR(__xludf.DUMMYFUNCTION("""COMPUTED_VALUE"""),"G-S25 256GB SILVER(2025)") -> G-S25 256GB SILVER(2025) | G15: =IFERROR(__xludf.DUMMYFUNCTION("""COMPUTED_VALUE"""),"RETURN") -> RETURN | H15: =IFERROR(__xludf.DUMMYFUNCTION("""COMPUTED_VALUE"""),46203.0) -> 46203 | J15: =IFERROR(__xludf.DUMMYFUNCTION("""COMPUTED_VALUE"""),"KHALIDA") -> KHALIDA | K15: =IFERROR(__xludf.DUMMYFUNCTION("""COMPUTED_VALUE"""),"DA CAMPAIGN") -> DA CAMPAIGN | L15: =IFERROR(__xludf.DUMMYFUNCTION("""COMPUTED_VALUE"""),"AVAILABLE IN AGENCY") -> AVAILABLE IN AGENCY | M15: =IFERROR(__xludf.DUMMYFUNCTION("""COMPUTED_VALUE"""),"LOANED / ON KOL") -> LOANED / ON KOL | N15: =IFERROR(__xludf.DUMMYFUNCTION("""COMPUTED_VALUE"""),"Satria ") -> Satria | P15: =IFERROR(__xludf.DUMMYFUNCTION("""COMPUTED_VALUE"""),"Layar Sudah ada baret dari penerimaan awal") -> Layar Sudah ada baret dari penerimaan awal
